<mujoco model="heating_pad">
  <compiler angle="radian" />
  <asset>
    <material name="mat_heating_pad" rgba="0.82 0.72 0.58 1" specular="0.18" shininess="0.12" />
    <material name="mat_pad_top" rgba="0.12 0.12 0.11 1" specular="0.55" shininess="0.45" />
    <material name="mat_pad_ring" rgba="0.93 0.86 0.74 1" specular="0.22" shininess="0.16" />
    <material name="mat_heat_plate" rgba="0.55 0.45 0.36 1" specular="0.40" shininess="0.30" />
    <material name="mat_switch_box" rgba="0.92 0.88 0.80 1" specular="0.18" shininess="0.12" />
    <material name="mat_switch_edge" rgba="0.50 0.38 0.27 1" specular="0.12" shininess="0.08" />
    <material name="mat_button" rgba="0.70 0.06 0.045 1" specular="0.40" shininess="0.30" />
    <material name="mat_cable" rgba="0.01 0.01 0.01 1" specular="0.08" shininess="0.04" />
    <material name="mat_led" rgba="1.0 0.18 0.04 1" specular="0.55" shininess="0.45" />
  </asset>
  <worldbody>
    <body>
      <body name="object">
        <body name="pad" pos="0 0 0">
          <site name="mug_region" type="box" pos="0 0 0.056" quat="1 0 0 0" size="0.062 0.062 0.004" rgba="0 0 0 0" />
          <geom name="pad_collision" type="cylinder" pos="0 0 0.024" size="0.088 0.024" material="mat_heating_pad" group="0" friction="1.0 0.3 0.1" />
          <geom name="pad_base_visual" type="cylinder" pos="0 0 0.022" size="0.091 0.020" material="mat_heating_pad" group="1" contype="0" conaffinity="0" />
          <geom name="pad_top_ring_visual" type="cylinder" pos="0 0 0.044" size="0.088 0.004" material="mat_pad_ring" group="1" contype="0" conaffinity="0" />
          <geom name="heat_plate_visual" type="cylinder" pos="0 0 0.049" size="0.064 0.003" material="mat_heat_plate" group="1" contype="0" conaffinity="0" />
          <geom name="black_ceramic_plate_visual" type="cylinder" pos="0 0 0.052" size="0.052 0.0015" material="mat_pad_top" group="1" contype="0" conaffinity="0" />
        </body>
        <body name="switch_box" pos="0 -0.142 0.022">
          <geom name="switch_box_collision" type="box" pos="0 0 0" size="0.040 0.052 0.013" material="mat_switch_box" group="0" friction="1.0 0.3 0.1" />
          <geom name="switch_box_visual" type="box" pos="0 0 0.002" size="0.039 0.051 0.012" material="mat_switch_box" group="1" contype="0" conaffinity="0" />
          <geom name="switch_box_front_edge_visual" type="box" pos="0 -0.052 0.004" size="0.041 0.002 0.012" material="mat_switch_edge" group="1" contype="0" conaffinity="0" />
          <geom name="switch_box_back_edge_visual" type="box" pos="0 0.052 0.004" size="0.041 0.002 0.012" material="mat_switch_edge" group="1" contype="0" conaffinity="0" />
          <geom name="switch_box_left_edge_visual" type="box" pos="-0.040 0 0.004" size="0.002 0.052 0.012" material="mat_switch_edge" group="1" contype="0" conaffinity="0" />
          <geom name="switch_box_right_edge_visual" type="box" pos="0.040 0 0.004" size="0.002 0.052 0.012" material="mat_switch_edge" group="1" contype="0" conaffinity="0" />
          <geom name="switch_led_lens_visual" type="cylinder" pos="0.022 0.016 0.018" size="0.007 0.002" material="mat_led" group="1" contype="0" conaffinity="0" />
          <body name="button" pos="-0.010 -0.004 0.025">
            <joint name="button" type="slide" pos="0 0 0" axis="0 0 1" limited="true" range="-0.008 0.0" damping="8.0" stiffness="2.0" springref="0.0" armature="0.02" />
            <geom name="button_collision" type="box" pos="0 0 0" size="0.018 0.022 0.006" material="mat_button" group="0" friction="0.45 0.10 0.02" solref="0.025 1" solimp="0.90 0.95 0.001" />
            <geom name="button_visual" type="box" pos="0 0 0.002" size="0.017 0.021 0.005" material="mat_button" group="1" contype="0" conaffinity="0" />
            <site name="indicator_on" type="cylinder" pos="0.032 0.020 0.004" quat="1 0 0 0" size="0.008 0.003" rgba="1 0.12 0.02 1" />
            <site name="indicator_off" type="cylinder" pos="0.032 0.020 0.0045" quat="1 0 0 0" size="0.008 0.003" rgba="0.05 0.85 0.20 0" />
          </body>
        </body>
        <geom name="power_cable_collision" type="capsule" fromto="0 -0.088 0.035 0 -0.142 0.035" size="0.006" material="mat_cable" group="0" friction="1.0 0.3 0.1" />
        <geom name="power_cable_pad_visual" type="capsule" fromto="0 -0.088 0.038 0 -0.112 0.038" size="0.005" material="mat_cable" group="1" contype="0" conaffinity="0" />
        <geom name="power_cable_box_visual" type="capsule" fromto="0 -0.112 0.038 0 -0.142 0.038" size="0.005" material="mat_cable" group="1" contype="0" conaffinity="0" />
      </body>
      <site rgba="0 0 0 0" size="0.06" pos="0 0 -0.005" name="bottom_site" />
      <site rgba="0 0 0 0" size="0.07" pos="0 0 0.064" name="top_site" />
      <site rgba="0 0 0 0" size="0.055" pos="0.055 0.055 0" name="horizontal_radius_site" />
    </body>
  </worldbody>
</mujoco>
