<mujoco model="heating_pad">
  <compiler angle="radian" />
  <asset>
    <material name="mat_heating_pad" rgba="0.36 0.38 0.40 1" specular="0.45" shininess="0.35" />
    <material name="mat_pad_top" rgba="0.58 0.60 0.62 1" specular="0.50" shininess="0.40" />
    <material name="mat_switch_box" rgba="0.78 0.78 0.72 1" specular="0.2" shininess="0.15" />
    <material name="mat_button" rgba="0.28 0.02 0.02 1" specular="0.35" shininess="0.3" />
    <material name="mat_cable" rgba="0.01 0.01 0.01 1" specular="0.08" shininess="0.04" />
  </asset>
  <worldbody>
    <body>
      <body name="object">
        <body name="pad" pos="0 0 0">
          <site name="mug_region" type="box" pos="0 0 0.056" quat="1 0 0 0" size="0.062 0.062 0.004" rgba="0 0 0 0" />
          <geom name="pad_collision" type="box" pos="0 0 0.024" size="0.088 0.088 0.024" material="mat_heating_pad" group="0" friction="1.0 0.3 0.1" />
          <geom name="pad_visual" type="box" pos="0 0 0.031" size="0.085 0.085 0.022" material="mat_pad_top" group="1" contype="0" conaffinity="0" />
        </body>
        <body name="switch_box" pos="0 -0.135 0.024">
          <geom name="switch_box_collision" type="box" pos="0 0 0" size="0.035 0.045 0.014" material="mat_switch_box" group="0" friction="1.0 0.3 0.1" />
          <geom name="switch_box_visual" type="box" pos="0 0 0.002" size="0.034 0.044 0.013" material="mat_switch_box" group="1" contype="0" conaffinity="0" />
          <body name="button" pos="-0.004 0 0.025">
            <joint name="button" type="slide" pos="0 0 0" axis="0 0 1" limited="true" range="-0.008 0.0" damping="8.0" stiffness="2.0" springref="0.0" armature="0.02" />
            <geom name="button_collision" type="cylinder" pos="0 0 0" size="0.018 0.006" material="mat_button" group="0" friction="0.35 0.08 0.02" solref="0.025 1" solimp="0.90 0.95 0.001" />
            <geom name="button_visual" type="cylinder" pos="0 0 0.002" size="0.017 0.005" material="mat_button" group="1" contype="0" conaffinity="0" />
            <site name="indicator" type="cylinder" pos="0 0 0.008" quat="1 0 0 0" size="0.018 0.003" rgba="1 0.02 0.01 0" />
          </body>
        </body>
        <geom name="power_cable_collision" type="capsule" fromto="0 -0.092 0.040 0 -0.135 0.040" size="0.007" material="mat_cable" group="0" friction="1.0 0.3 0.1" />
        <geom name="power_cable_pad_visual" type="capsule" fromto="0 -0.092 0.043 0 -0.112 0.043" size="0.006" material="mat_cable" group="1" contype="0" conaffinity="0" />
        <geom name="power_cable_box_visual" type="capsule" fromto="0 -0.112 0.043 0 -0.135 0.043" size="0.006" material="mat_cable" group="1" contype="0" conaffinity="0" />
      </body>
      <site rgba="0 0 0 0" size="0.06" pos="0 0 -0.005" name="bottom_site" />
      <site rgba="0 0 0 0" size="0.07" pos="0 0 0.064" name="top_site" />
      <site rgba="0 0 0 0" size="0.055" pos="0.055 0.055 0" name="horizontal_radius_site" />
    </body>
  </worldbody>
</mujoco>
