<mujoco model="cardboard_box">
  <compiler angle="radian" />
  <asset>
    <material name="cardboard_outer" rgba="0.72 0.56 0.34 1" specular="0.015" shininess="0.01" />
    <material name="cardboard_inner" rgba="0.76 0.58 0.34 1" specular="0.01" shininess="0.01" />
    <material name="cardboard_edge" rgba="0.52 0.38 0.20 1" specular="0.01" shininess="0.01" />
  </asset>
  <worldbody>
    <body>
      <body name="object">
        <site name="contain_region" type="box" pos="0 0 0.086" quat="1 0 0 0" size="0.062 0.052 0.070" rgba="0 0 0 0" />

        <geom name="box_bottom_collision" type="box" pos="0 0 0.020" size="0.068 0.058 0.020" rgba="0.76 0.58 0.34 1" group="0" friction="0.95 0.3 0.1" />
        <geom name="box_front_collision" type="box" pos="0 -0.058 0.074" size="0.068 0.0040 0.066" material="cardboard_outer" group="0" friction="1.05 0.35 0.1" solref="0.010 1" solimp="0.90 0.98 0.001" />
        <geom name="box_back_collision" type="box" pos="0 0.058 0.074" size="0.068 0.0040 0.066" material="cardboard_outer" group="0" friction="1.05 0.35 0.1" solref="0.010 1" solimp="0.90 0.98 0.001" />
        <geom name="box_left_collision" type="box" pos="-0.068 0 0.074" size="0.0040 0.058 0.066" material="cardboard_outer" group="0" friction="1.05 0.35 0.1" solref="0.010 1" solimp="0.90 0.98 0.001" />
        <geom name="box_right_collision" type="box" pos="0.068 0 0.074" size="0.0040 0.058 0.066" material="cardboard_outer" group="0" friction="1.05 0.35 0.1" solref="0.010 1" solimp="0.90 0.98 0.001" />

        <geom name="box_bottom_visual" type="box" pos="0 0 0.020" size="0.067 0.057 0.020" rgba="0.76 0.58 0.34 1" group="1" contype="0" conaffinity="0" />
        <geom name="box_inner_floor_visual" type="box" pos="0 0 0.044" size="0.061 0.051 0.005" rgba="0.76 0.58 0.34 1" group="1" contype="0" conaffinity="0" />
        <geom name="box_front_visual" type="box" pos="0 -0.056 0.075" size="0.067 0.0012 0.065" material="cardboard_outer" group="1" contype="0" conaffinity="0" />
        <geom name="box_back_visual" type="box" pos="0 0.056 0.075" size="0.067 0.0012 0.065" material="cardboard_outer" group="1" contype="0" conaffinity="0" />
        <geom name="box_left_visual" type="box" pos="-0.066 0 0.075" size="0.0012 0.057 0.065" material="cardboard_outer" group="1" contype="0" conaffinity="0" />
        <geom name="box_right_visual" type="box" pos="0.066 0 0.075" size="0.0012 0.057 0.065" material="cardboard_outer" group="1" contype="0" conaffinity="0" />
        <geom name="front_top_edge_visual" type="box" pos="0 -0.058 0.141" size="0.069 0.0012 0.0012" material="cardboard_edge" group="1" contype="0" conaffinity="0" />
        <geom name="left_top_edge_visual" type="box" pos="-0.068 0 0.141" size="0.0012 0.058 0.0012" material="cardboard_edge" group="1" contype="0" conaffinity="0" />
        <geom name="right_top_edge_visual" type="box" pos="0.068 0 0.141" size="0.0012 0.058 0.0012" material="cardboard_edge" group="1" contype="0" conaffinity="0" />

        <body name="lid_hinge_body" pos="0 0.058 0.142">
          <joint name="lid_hinge" type="hinge" pos="0 0 0" axis="1 0 0" limited="true" range="-2.75 0.02" damping="4.0" armature="0.004" frictionloss="0.025" />
          <geom name="attached_lid_collision" type="box" pos="0 -0.056 0.004" size="0.069 0.054 0.0015" material="cardboard_outer" group="0" friction="1.0 0.3 0.1" mass="0.012" />
          <geom name="attached_lid_visual" type="box" pos="0 -0.056 0.005" size="0.071 0.056 0.0018" material="cardboard_outer" group="1" contype="0" conaffinity="0" />
          <geom name="attached_lid_fold_line" type="box" pos="0 -0.006 0.009" size="0.070 0.0012 0.0012" material="cardboard_edge" group="1" contype="0" conaffinity="0" />
        </body>
      </body>
      <site rgba="0 0 0 0" size="0.005" pos="0 0 -0.004" name="bottom_site" />
      <site rgba="0 0 0 0" size="0.005" pos="0 0 0.150" name="top_site" />
      <site rgba="0 0 0 0" size="0.078" pos="0.078 0.078 0" name="horizontal_radius_site" />
    </body>
  </worldbody>
</mujoco>
